Workbook

Sheet RECEITA
A1: Mara Nery
A2: CNPJ: 00.000.000/0001-00
A3: Ref.: | B3: Março/2025 | | C3: =TODAY() -> 46107
A4: CONTROLE RECEITA MENSAL
A6: RESUMO FINANCEIRO
A7: Total Bruto a Receber: | C7: =SUM(Tabela1[VALOR TOTAL (R$)]) -> 57740.65
A8: Total A Receber: | C8: =SUM(Tabela1[VALOR TOTAL (R$)]) -> 57740.65 | D8: Boleto: | E8: =SUMIF(H16:H28,"Boleto",L16:L28) -> 28780.088
A9: Total Pendente: | C9: =SUMIF(I16:I28,"Pendente",G16:G28) -> 2896.15 | D9: Cartão: | E9: =SUMIF(H16:H28,"Cartão",L16:L28) -> 1237.5 | F9: Recebido: | G9: =E11/C8 -> 0.73970656
A10: Total em Atraso: | C10: =SUMIF(I16:I28,"Atrasado",G16:G28) -> 14647.51 | D10: Depósito: | E10: =SUMIF(H16:H28,"Depósito",L16:L28) -> 12693.55 | F10: Em atraso: | G10: =C10/C8 -> 0.25367761
D11: Total Entrada: | E11: =SUM(E8:E10) -> 42711.138
A15: ID | B15: CLIENTE | C15: DESCRIÇÃO | D15: CATEGORIA | E15: EMISSÃO | F15: VENCIMENTO | G15: VALOR TOTAL (R$) | H15: BOLETO | I15: STATUS | J15: DATA RECEBIMENTO | K15: DESCONTO (-) ACRÉSCIMO (+) (R$) | L15: VALOR FINAL (R$) | M15: OBSERVAÇÕES
A16: 1 | B16: Empresa A | C16: - | D16: Venda | E16: 46054 | F16: 46082 | G16: 3500 | H16: Depósito | I16: =IF(J16>0,"Recebido",IF(AND(TODAY()>F16,J16=0),"Atrasado","Pendente")) -> Recebido | J16: 46082 | K16: =IF(I16<>"Recebido","",IF(J16<F16,-G16*1%,IF(J16>F16,(J16-F16)*G16*6%,0))) -> 0 | L16: =IF(I16="Recebido",G16+IF(K16="",0,K16),"") -> 3500
A17: 2 | B17: Empresa B | C17: - | D17: Venda | E17: 46056 | F17: 46084 | G17: 3200.5 | H17: Depósito | I17: =IF(J17>0,"Recebido",IF(AND(TODAY()>F17,J17=0),"Atrasado","Pendente")) -> Recebido | J17: 46085 | K17: =IF(I17<>"Recebido","",IF(J17<F17,-G17*1%,IF(J17>F17,(J17-F17)*G17*6%,0))) -> 192.03 | L17: =IF(I17="Recebido",G17+IF(K17="",0,K17),"") -> 3392.53
A18: 35 | B18: Empresa C | C18: - | D18: Venda | E18: 46058 | F18: 46086 | G18: 2400 | H18: Depósito | I18: =IF(J18>0,"Recebido",IF(AND(TODAY()>F18,J18=0),"Atrasado","Pendente")) -> Atrasado | K18: =IF(I18<>"Recebido","",IF(J18<F18,-G18*5%,IF(J18>F18,(J18-F18)*G18*6%,0))) | L18: =IF(I18="Recebido",G18+IF(K18="",0,K18),"")
A19: 15 | B19: Empresa D | C19: Produto x | D19: Locação | E19: 46060 | F19: 46180 | G19: 1250 | H19: Cartão | I19: =IF(J19>0,"Recebido",IF(AND(TODAY()>F19,J19=0),"Atrasado","Pendente")) -> Recebido | J19: 46088 | K19: =IF(I19<>"Recebido","",IF(J19<F19,-G19*1%,IF(J19>F19,(J19-F19)*G19*6%,0))) -> -12.5 | L19: =IF(I19="Recebido",G19+IF(K19="",0,K19),"") -> 1237.5
A20: 153 | B20: Empresa E | C20: - | D20: Venda | E20: 46078 | F20: 46106 | G20: 5876.12 | H20: Boleto | I20: =IF(J20>0,"Recebido",IF(AND(TODAY()>F20,J20=0),"Atrasado","Pendente")) -> Atrasado | K20: =IF(I20<>"Recebido","",IF(J20<F20,-G20*1%,IF(J20>F20,(J20-F20)*G20*6%,0))) | L20: =IF(I20="Recebido",G20+IF(K20="",0,K20),"")
A21: 23 | B21: Empresa F | C21: - | D21: Venda | E21: 46063 | F21: 46106 | G21: 7895.23 | H21: Boleto | I21: =IF(J21>0,"Recebido",IF(AND(TODAY()>F21,J21=0),"Atrasado","Pendente")) -> Recebido | J21: 46091 | K21: =IF(I21<>"Recebido","",IF(J21<F21,-G21*1%,IF(J21>F21,(J21-F21)*G21*6%,0))) -> -78.9523 | L21: =IF(I21="Recebido",G21+IF(K21="",0,K21),"") -> 7816.2777
A22: 58 | B22: Empresa G | C22: - | D22: Venda | E22: 46072 | F22: 46099 | G22: 12845 | H22: Boleto | I22: =IF(J22>0,"Recebido",IF(AND(TODAY()>F22,J22=0),"Atrasado","Pendente")) -> Recebido | J22: 46098 | K22: =IF(I22<>"Recebido","",IF(J22<F22,-G22*1%,IF(J22>F22,(J22-F22)*G22*6%,0))) -> -128.45 | L22: =IF(I22="Recebido",G22+IF(K22="",0,K22),"") -> 12716.55
A23: 136 | B23: Empresa H | C23: Produto x | D23: Locação | E23: 46074 | F23: 46102 | G23: 1245 | H23: Cartão | I23: =IF(J23>0,"Recebido",IF(AND(TODAY()>F23,J23=0),"Atrasado","Pendente")) -> Atrasado | K23: =IF(I23<>"Recebido","",IF(J23<F23,-G23*1%,IF(J23>F23,(J23-F23)*G23*6%,0))) | L23: =IF(I23="Recebido",G23+IF(K23="",0,K23),"")
A24: 8956 | B24: Empresa I | C24: - | D24: Venda | E24: 46060 | F24: 46088 | G24: 3259 | H24: Depósito | I24: =IF(J24>0,"Recebido",IF(AND(TODAY()>F24,J24=0),"Atrasado","Pendente")) -> Recebido | J24: 46101 | K24: =IF(I24<>"Recebido","",IF(J24<F24,-G24*1%,IF(J24>F24,(J24-F24)*G24*6%,0))) -> 2542.02 | L24: =IF(I24="Recebido",G24+IF(K24="",0,K24),"") -> 5801.02
A25: 835 | B25: Empresa J | C25: - | D25: Venda | E25: 46071 | F25: 46100 | G25: 8247.26 | H25: Boleto | I25: =IF(J25>0,"Recebido",IF(AND(TODAY()>F25,J25=0),"Atrasado","Pendente")) -> Recebido | J25: 46100 | K25: =IF(I25<>"Recebido","",IF(J25<F25,-G25*1%,IF(J25>F25,(J25-F25)*G25*6%,0))) -> 0 | L25: =IF(I25="Recebido",G25+IF(K25="",0,K25),"") -> 8247.26
A26: 5369 | B26: Empresa K | C26: - | D26: Venda | E26: 46068 | F26: 46096 | G26: 5126.39 | H26: Boleto | I26: =IF(J26>0,"Recebido",IF(AND(TODAY()>F26,J26=0),"Atrasado","Pendente")) -> Atrasado | K26: =IF(I26<>"Recebido","",IF(J26<F26,-G26*1%,IF(J26>F26,(J26-F26)*G26*6%,0))) | L26: =IF(I26="Recebido",G26+IF(K26="",0,K26),"")
A27: 2588 | B27: Empresa L | C27: Produto Y | D27: Locação | E27: 46081 | F27: 46112 | G27: 2896.15 | H27: Depósito | I27: =IF(J27>0,"Recebido",IF(AND(TODAY()>F27,J27=0),"Atrasado","Pendente")) -> Pendente | K27: =IF(I27<>"Recebido","",IF(J27<F27,-G27*1%,IF(J27>F27,(J27-F27)*G27*6%,0))) | L27: =IF(I27="Recebido",G27+IF(K27="",0,K27),"")
M33: Developed by Mara N,

Sheet DESPESA
A1: Mara Nery
A2: CNPJ: 00.000.000/0001-00
A3: Ref.: | B3: Março/2025 | | C3: =TODAY() -> 46107
A4: CONTROLE DESPESA MENSAL
A6: RESUMO FINANCEIRO
A7: Total Bruto a Pagar: | C7: =SUM(Tabela2[VALOR TOTAL (R$)]) -> 167793.31
A8: Total A Pagar: | C8: =SUM(Tabela2[VALOR TOTAL (R$)]) -> 167793.31 | E8: Boleto: | F8: =SUMIF(F15:F29,"Boleto",M15:M29) -> 43756.04 | H8: Pago: | I8: =F10/C8 -> 0.73498276
A9: Total Em Aberto: | C9: =SUMIF(J15:J30,"Em Aberto",H15:H30) -> 31823.43 | E9: Depósito: | F9: =SUMIF(F15:F30,"Depósito",M15:M30) -> 79569.15 | H9: Em aberto: | I9: =C9/C8 -> 0.18965851
A10: Total Em Atraso: | C10: =SUMIF(J16:J31,"Atrasado",H16:H31) -> 12590.75 | E10: Total Final: | F10: =SUM(F8:F9) -> 123325.19 | H10: Em atraso: | I10: =C10/C8 -> 0.075037259
A14: ID | B14: FORNECEDOR | C14: DESCRIÇÃO | D14: CATEGORIA | E14: EMISSÃO | F14: RECEBIMENTO | G14: VENCIMENTO | H14: VALOR TOTAL (R$) | I14: PAGAMENTO | J14: STATUS | K14: DESCONTO (R$) | L14: JUROS (R$) | M14: VALOR FINAL (R$) | N14: OBSERVAÇÕES
A15: 1 | B15: Neoenergia | C15: Energia | D15: Operacional | E15: 46054 | F15: Boleto | G15: 46082 | H15: 896.25 | I15: 46082 | J15: =IF(I15>0,"Quitado",IF(AND(TODAY()>G15,I15=0),"Atrasado","Em Aberto")) -> Quitado | K15: 0 | L15: 0 | M15: =IF(J15="Quitado",H15-K15+L15,"") -> 896.25
A16: 42 | B16: Empresa B | C16: Internet | D16: Operacional | E16: 46058 | F16: Depósito | G16: 46085 | H16: 350 | J16: =IF(I16>0,"Quitado",IF(AND(TODAY()>G16,I16=0),"Atrasado","Em Aberto")) -> Atrasado | M16: =IF(J16="Quitado",H16-K16+L16,"")
A17: 2 | B17: Empresa C | C17: Office Supplies | D17: Operacional | E17: 46062 | F17: Boleto | G17: 46086 | H17: 419.25 | I17: 46086 | J17: =IF(I17>0,"Quitado",IF(AND(TODAY()>G17,I17=0),"Atrasado","Em Aberto")) -> Quitado | K17: 0 | L17: 0 | M17: =IF(J17="Quitado",H17-K17+L17,"") -> 419.25
A18: 35 | B18: Empresa D | C18: Telefonia | D18: Operacional | E18: 46070 | F18: Boleto | G18: 46096 | H18: 689.27 | J18: =IF(I18>0,"Quitado",IF(AND(TODAY()>G18,I18=0),"Atrasado","Em Aberto")) -> Atrasado | M18: =IF(J18="Quitado",H18-K18+L18,"")
A19: 15 | B19: Simples Nacional | C19: Imposto | D19: Financeiro | E19: 46070 | F19: Boleto | G19: 46094 | H19: 29863.89 | I19: 46096 | J19: =IF(I19>0,"Quitado",IF(AND(TODAY()>G19,I19=0),"Atrasado","Em Aberto")) -> Quitado | K19: 0 | L19: 35.06 | M19: =IF(J19="Quitado",H19-K19+L19,"") -> 29898.95
A20: 153 | B20: Alvará | C20: Licença | D20: Administrativo | E20: 46078 | F20: Depósito | G20: 46101 | H20: 8651.59 | J20: =IF(I20>0,"Quitado",IF(AND(TODAY()>G20,I20=0),"Atrasado","Em Aberto")) -> Atrasado | M20: =IF(J20="Quitado",H20-K20+L20,"")
A21: 23 | B21: F. de Pagamento | C21: Salários | D21: Operacional | E21: 46076 | F21: Depósito | G21: 46086 | H21: 79569.15 | I21: 46082 | J21: =IF(I21>0,"Quitado",IF(AND(TODAY()>G21,I21=0),"Atrasado","Em Aberto")) -> Quitado | M21: =IF(J21="Quitado",H21-K21+L21,"") -> 79569.15
A22: 58 | B22: Empresa H | C22: Geladeira | D22: Investimento | E22: 46073 | F22: Boleto | G22: 46101 | H22: 2899.89 | J22: =IF(I22>0,"Quitado",IF(AND(TODAY()>G22,I22=0),"Atrasado","Em Aberto")) -> Atrasado | M22: =IF(J22="Quitado",H22-K22+L22,"")
A23: 136 | B23: DAS MEI | C23: Imposto | D23: Financeiro | E23: 46074 | F23: Boleto | G23: 46096 | H23: 12630.59 | I23: 45823 | J23: =IF(I23>0,"Quitado",IF(AND(TODAY()>G23,I23=0),"Atrasado","Em Aberto")) -> Quitado | K23: 89 | L23: 0 | M23: =IF(J23="Quitado",H23-K23+L23,"") -> 12541.59
A24: 8956 | B24: Empresa J | C24: Site | D24: Administrativo | E24: 46073 | F24: Boleto | G24: 46112 | H24: 399 | J24: =IF(I24>0,"Quitado",IF(AND(TODAY()>G24,I24=0),"Atrasado","Em Aberto")) -> Em Aberto | M24: =IF(J24="Quitado",H24-K24+L24,"")
A25: 835 | B25: ICMS | C25: Imposto | D25: Financeiro | E25: 46078 | F25: Boleto | G25: 46110 | H25: 4659.54 | J25: =IF(I25>0,"Quitado",IF(AND(TODAY()>G25,I25=0),"Atrasado","Em Aberto")) -> Em Aberto | M25: =IF(J25="Quitado",H25-K25+L25,"")
A26: 5369 | B26: Empresa K | C26: Segurança Priv | D26: Operacional | E26: 46081 | F26: Depósito | G26: 46112 | H26: 639.2 | J26: =IF(I26>0,"Quitado",IF(AND(TODAY()>G26,I26=0),"Atrasado","Em Aberto")) -> Em Aberto | M26: =IF(J26="Quitado",H26-K26+L26,"")
A27: 2588 | B27: Vale Transporte | C27: Colaboradores | D27: Operacional | E27: 46080 | F27: Depósito | G27: 46110 | H27: 26125.69 | J27: =IF(I27>0,"Quitado",IF(AND(TODAY()>G27,I27=0),"Atrasado","Em Aberto")) -> Em Aberto | M27: =IF(J27="Quitado",H27-K27+L27,"")
N35: Developed by Mara N,
G42: 4

Sheet DASHBOARD
B2: ANÁLISE FINANCEIRO GERENCIAL
B3: Análise de Desempenho, Risco e Eficiência Financeira do Período | O3: MARÇO/2026'
B5: RECEITA
B6: RECEITA BRUTA DO MÊS | G6: RECEBIDO (CAIXA) | L6: EM RISCO DE RECEBER
B7: =_DadosAux!B1 -> 57740.65 | G7: =_DadosAux!B2 -> 12693.55 | L7: =_DadosAux!B33 -> 17543.66
B8: Fórmula: =RECEITA!C7 — Clientes no período: | G8: Fórmula: =RECEITA!E10 — Eficiência de cobrança: | L8: Fórmula: =RECEITA!C9+RECEITA!C10 — Pendente + Atrasado
G9: =IFERROR(_DadosAux!B2/_DadosAux!B1,0) -> 0.21983732 | L9: =IFERROR(_DadosAux!B33/_DadosAux!B1,0) -> 0.30383551
B11: DESPESA
B12: DESPESA BRUTA DO MÊS | G12: TOTAL PAGO | L12: EM ABERTO + ATRASADO
B13: =_DadosAux!B15 -> 167793.31 | G13: =_DadosAux!B16 -> 123325.19 | L13: =_DadosAux!B34 -> 44414.18
B14: Fórmula: =DESPESA!C7 — Lançamentos: | G14: Fórmula: =DESPESA!F10 — % sobre bruto: | L14: Fórmula: =DESPESA!C9+DESPESA!C10 — Risco de caixa:
G15: =IFERROR(_DadosAux!B16/_DadosAux!B15,0) -> 0.73498276 | L15: =IFERROR(_DadosAux!B34/_DadosAux!B15,0) -> 0.26469577
B17: GERENCIAIS
B18: SALDO DE CAIXA REAL | G18: COMPROMETIMENTO FINANC. | L18: TICKET MÉDIO DE RECEITA
B19: =_DadosAux!B28 -> -110631.64 | G19: =_DadosAux!B30 -> 9.7155792 | L19: =_DadosAux!B35 -> 4811.7208
B20: Fórmula: =Recebido − Pago — Margem líquida: | G20: Fórmula: =Pago÷Recebido — Desp paga ÷ Rec recebida | L20: Fórmula: =Bruto÷Qtd.Clientes — Ticket médio despesa:
B21: =IFERROR((_DadosAux!B2-_DadosAux!B16)/_DadosAux!B2,0) -> -8.7155792
B23: PAINEL DE ALERTAS E RISCOS
B24: ⚠ | C24: =IFERROR("Receitas em atraso: "&_DadosAux!B11&" cliente(s) totalizando R$ "&TEXT(_DadosAux!B4,"#,##"),"Ver aba RECEITA") -> Receitas em atraso: 4 cliente(s) totalizando R$ 14647,51 | G24: 🔴 | H24: =IFERROR("Despesas em aberto: "&_DadosAux!B26&" item(ns) → R$ "&TEXT(_DadosAux!B17,"#,##")&" a pagar","Ver DESPESA") -> Despesas em aberto: 4 item(ns) → R$ 31823,43 a pagar | L24: 📉 | M24: =IF(_DadosAux!B30>1,"CRITICO: despesas superam receitas em R$ "&TEXT(ABS(_DadosAux!B28),"#,##"),IF(_DadosAux!B30>0.8,"ATENCAO: comprometimento acima de 80%","Comprometimento dentro do limite")) -> CRITICO: despesas superam receitas em R$ 110631,64
B25: 🔔 | C25: =IFERROR("Despesas atrasadas: "&_DadosAux!B25&" item(ns) → R$ "&TEXT(_DadosAux!B18,"#,##")&" em risco de multa","Ver DESPESA") -> Despesas atrasadas: 4 item(ns) → R$ 12590,75 em risco de multa | G25: ✅ | H25: =IF(_DadosAux!B31>=0.8,"Cobrança eficiente: "&TEXT(_DadosAux!B31,"0.0%")&" recebido vs faturado","ATENCAO: cobrança em "&TEXT(_DadosAux!B31,"0.0%")&" < 80%") -> ATENCAO: cobrança em 22% < 80% | L25: 💡 | M25: =IF(_DadosAux!B28>=0,"Resultado POSITIVO: R$ "&TEXT(_DadosAux!B28,"#,##")&" de superavit","Resultado NEGATIVO: R$ "&TEXT(ABS(_DadosAux!B28),"#,##")&" de deficit") -> Resultado NEGATIVO: R$ 110631,64 de deficit
B27: RESUMO FINANCEIRO
B28: INDICADOR | F28: RECEITA (R$) | I28: DESPESA (R$) | L28: VARIAÇÃO (R$) | N28: % S/ BRUTO REC.
B29: Bruto Total (Faturado/Lançado) | F29: =_DadosAux!B1 -> 57740.65 | I29: =_DadosAux!B15 -> 167793.31 | L29: =_DadosAux!B1-_DadosAux!B15 -> -110052.66 | N29: =IFERROR(_DadosAux!B1/_DadosAux!B1,0) -> 1
B30: Realizado (Recebido / Pago) | F30: =_DadosAux!B2 -> 12693.55 | I30: =_DadosAux!B16 -> 123325.19 | L30: =_DadosAux!B2-_DadosAux!B16 -> -110631.64 | N30: =IFERROR(_DadosAux!B2/_DadosAux!B1,0) -> 0.21983732
B31: Pendente / Em Aberto | F31: =_DadosAux!B3 -> 2896.15 | I31: =_DadosAux!B17 -> 31823.43 | L31: =_DadosAux!B3-_DadosAux!B17 -> -28927.28 | N31: =IFERROR(_DadosAux!B3/_DadosAux!B1,0) -> 0.050157904
B32: Atrasado (vencido não liquidado) | F32: =_DadosAux!B4 -> 14647.51 | I32: =_DadosAux!B18 -> 12590.75 | L32: =_DadosAux!B4-_DadosAux!B18 -> 2056.76 | N32: =IFERROR(_DadosAux!B4/_DadosAux!B1,0) -> 0.25367761
B33: Ticket Médio (por cliente/lanç.) | F33: =_DadosAux!B35 -> 4811.7208 | I33: =_DadosAux!B36 -> 12907.178 | L33: =_DadosAux!B35-_DadosAux!B36 -> -8095.4569 | N33: =IFERROR(_DadosAux!B35/_DadosAux!B1,0) -> 0.083333333
B34: TOTAIS DO PERÍODO | F34: =_DadosAux!B1 -> 57740.65 | I34: =_DadosAux!B15 -> 167793.31 | L34: =_DadosAux!B1-_DadosAux!B15 -> -110052.66 | N34: =IFERROR(_DadosAux!B2/_DadosAux!B1,0) -> 0.21983732
B36: ANÁLISE GRÁFICA
B37: Receitas por Status | G37: Despesas por Status | L37: Despesas por Categoria
B55: Receita vs Despesa — Bruto × Realizado × Em Risco | I55: Receita por Categoria | M55: Eficiência de Cobrança vs Pagamento
N79: Developed by Mara N,

Sheet base_dado_
A2: FÓRMULAS — FINANCEIRO GERENCIAL
A3: Documentação técnica: cada indicador, fórmula, posicionamento e lógica analítica — Use este guia para auditar e/ou replicar o dashboard
A4: ▸ ESTRUTURA GERAL DO ARQUIVO
B5: Aba RECEITA | C5: Linhas 16-27 (dados), L7,L10,L9,L10 | D5: Contém o lançamento de cada cliente: ID, Nome, Categoria, Emissão, Vencimento, Valor Total, Forma de Pagamento, Status (Recebido/Pendente/Atrasado), Data de Recebimento, Desconto/Acréscimo, Valor Final. Os totalizadores estão nas linhas 7-10.
B6: Aba DESPESA | C6: Linhas 15-27 (dados), C7,F10,C9,C10 | D6: Contém lançamentos de despesas: ID, Fornecedor, Descrição, Categoria (Operacional/Financeiro/Administrativo/Investimento), Emissão, Forma, Vencimento, Valor Total, Data Pagamento, Status (Quitado/Em Aberto/Atrasado), Desconto, Juros, Valor Final.
B7: Aba _DadosAux (oculta) | C7: Agregadores e séries de gráficos | D7: Aba auxiliar oculta que centraliza todas as fórmulas de agregação (SUMIF, COUNTIF, cálculos derivados). O DASHBOARD lê apenas desta aba, tornando as fórmulas do dashboard simples e à prova de erros.
A8: ▸ SEÇÃO 1 — INDICADORES DE RECEITA (Linhas 5-8)
B9: Receita Bruta do Mês | C9: =RECEITA!C7 -> 57740.65 | D9: Puxa diretamente a célula C7 da aba RECEITA, que contém "Total Bruto a Receber". Representa o faturamento total emitido no mês, independente de ter sido recebido. É o topo da pirâmide de receitas.
B10: Total Recebido | C10: =RECEITA!E10 -> 12693.55 | D10: Puxa "Total Entrada" da aba RECEITA (célula E10). Este é o valor efetivamente recebido em caixa - soma de todos os lançamentos com status "Recebido" na coluna VALOR FINAL. É o único que representa dinheiro real no caixa.
B11: Saldo em Risco de Receber | C11: =RECEITA!C9+RECEITA!C10 -> 17543.66 | D11: Pendente (C9) = vencimento futuro, ainda não recebido. Atrasado (C10) = vencimento já passou sem recebimento. A soma é o total que pode não ser convertido em caixa - risco de inadimplência.
B12: Eficiência de Cobrança | C12: =IFERROR(B2/B1,0) -> 0 | D12: Recebido ÷ Bruto. Indica qual percentual do faturado foi efetivamente recebido. Meta saudável: ≥90%. Entre 70-90%: atenção. Abaixo de 70%: problema sério de inadimplência. IFERROR protege contra divisão por zero.
B13: Qtd. Clientes | C13: =COUNTA(RECEITA!A16:A27) -> 12 | D13: COUNTA conta quantas células não-vazias existem na coluna ID da aba RECEITA entre as linhas 16 e 27. Cada linha é um cliente/lançamento. Não usa COUNT (numérico) para evitar erro se o ID for texto.
B14: Receita por Categoria | C14: =SUMIF(RECEITA!D16:D27,"Venda",RECEITA!G16:G27) -> 52349.5 | D14: SUMIF: 1º parâmetro = intervalo de critério (col D, CATEGORIA); 2º = critério ("Venda" ou "Locação"); 3º = intervalo de soma (col G, VALOR TOTAL). Agrupa receitas por tipo de venda para análise de mix de produtos.
A15: ▸ SEÇÃO 2 — INDICADORES DE DESPESA (Linhas 10-13)
B16: Despesa Bruta do Mês | C16: =DESPESA!C7 -> 167793.31 | D16: Puxa "Total Bruto a Pagar" da aba DESPESA, célula C7. Representa o total de compromissos financeiros do período - todos os lançamentos, independente de pagamento.
B17: Total Pago | C17: =DESPESA!F10 -> 123325.19 | D17: Puxa "Total Final" da aba DESPESA (célula F10). Este valor reflete saídas reais de caixa - soma de todos os itens com status "Quitado", já considerando descontos obtidos e juros pagos.
B18: Em Aberto + Atrasado | C18: =DESPESA!C9+DESPESA!C10 -> 44414.18 | D18: Em Aberto (C9) = despesas com vencimento futuro ainda não pagas. Atrasado (C10) = despesas com vencimento passado não pagas. Juntos formam o "passivo pendente" - risco de saída de caixa iminente.
B19: Despesa por Categoria | C19: =SUMIF(DESPESA!D15:D27,"Operacional",DESPESA!H15:H27) -> 108688.81 | D19: SUMIF na aba DESPESA: agrupa por Categoria (col D) somando Valor Total (col H). As categorias são: Operacional (custo corrente), Financeiro (impostos/tributos), Administrativo (licenças/contratos), Investimento (ativos/capex).
B20: % Pago sobre Bruto | C20: =IFERROR(B16/B15,0) -> 0 | D20: Pago ÷ Bruto Despesa. Indica quantos % do total de compromissos foi quitado. 100% = tudo pago. Abaixo de 70% = muitas pendências. IFERROR evita erro se não há despesas.
A21: ▸ SEÇÃO 3 — INDICADORES GERENCIAIS (Linhas 15-18)
B22: Resultado do Mês | C22: =_DadosAux!B2-_DadosAux!B16 -> -110631.64 | D22: Recebido MENOS Pago. Se positivo: sobraram recursos (superávit). Se negativo: saiu mais do que entrou (déficit). Atenção: diferente de Receita Bruta - Despesa Bruta, pois usa apenas os valores realizados de fato.
B23: Margem Líquida | C23: =IFERROR((B2-B16)/B2,0) -> 0 | D23: (Recebido - Pago) ÷ Recebido. Percentual que sobra do total recebido após quitar todas as despesas. Exemplo: 20% de margem = R$ 0,20 de lucro para cada R$ 1,00 recebido. IFERROR protege divisão por zero.
B24: Comprometimento Financeiro | C24: =IFERROR(B16/B2,0) -> 0 | D24: Despesa Paga ÷ Receita Recebida. Indica o quanto da receita está comprometida com despesas. >100% = insolvência no período. 80-100% = zona de perigo. <60% = situação saudável. Inverso da margem.
B25: Lógica IF de Alerta | C25: =IF(B30>1,"CRITICO",IF(B30>0.8,"ATENCAO","OK")) -> CRITICO | D25: IF aninhado: verifica se comprometimento > 100% (crítico: déficit real). Se não, verifica > 80% (atenção: quase sem margem). Caso contrário, exibe mensagem positiva. Funciona como semáforo dinâmico.
B26: Ticket Médio Receita | C26: =IFERROR(B1/B8,0) -> 0 | D26: Receita Bruta ÷ Quantidade de Clientes. Valor médio de cada lançamento de receita. Útil para identificar concentração: ticket alto com poucos clientes = risco de dependência.
B27: Ticket Médio Despesa | C27: =IFERROR(B15/B23,0) -> 0 | D27: Despesa Bruta ÷ Quantidade de Lançamentos. Tamanho médio de cada compromisso de despesa. Comparar com ticket de receita: se desp > rec, cada despesa é mais pesada que cada receita - alerta de estrutura de custos.
A28: ▸ SEÇÃO 4 — PAINEL DE ALERTAS (Linhas 20-22)
B29: Alerta Atraso Receita | C29: =COUNTIF(RECEITA!I16:I27,"Atrasado") -> 4 | D29: COUNTIF conta quantos clientes têm status "Atrasado" na coluna I (STATUS) da aba RECEITA entre linhas 16-27. Cada unidade = 1 cliente inadimplente. Usado em conjunto com TEXT para exibir mensagem formatada.
B30: Alerta Em Aberto Despesa | C30: =COUNTIF(DESPESA!J15:J27,"Em Aberto") -> 4 | D30: COUNTIF na coluna J (STATUS) da aba DESPESA. Conta itens com status "Em Aberto" = vencimento futuro não pago. Diferente de "Atrasado" - estes ainda estão no prazo.
B31: Alerta Atrasado Despesa | C31: =COUNTIF(DESPESA!J15:J27,"Atrasado") -> 4 | D31: Conta despesas com vencimento já passado e não pagas. Cada unidade representa risco de multa, juros e protestos. Mensagem concatenada com TEXT para mostrar o valor total em risco.
B32: Eficiência de Cobrança | C32: =IF(B31>=0.8,"✓ OK: "&TEXT(B31,"0.0%"),"⚠ "&TEXT(B31,"0.0%")) -> ✓ OK: Alerta Atrasado Despesa | D32: IF que verifica se eficiência ≥ 80%. Em caso positivo, confirma com ícone ✓. Se negativo, exibe ⚠ alertando que o nível de inadimplência está acima do tolerável.
B33: Resultado Semáforo | C33: =IF(B28>=0,"POSITIVO: R$ "&TEXT(B28,"#,##0.00"),"NEGATIVO: R$ "&TEXT(ABS(B28),"#,##0.00")) -> POSITIVO: R$ ,000 | D33: IF + TEXT: verifica se resultado ≥ 0. Se sim, exibe superávit formatado. Se negativo, usa ABS() para evitar o sinal negativo no texto e exibe "déficit" de forma legível.
A34: ▸ SEÇÃO 5 — TABELA RESUMO (Linhas 24-31)
B35: Posicionamento | C35: Linhas 25-31, colunas B até O | D35: 5 linhas de dados + 1 cabeçalho + 1 total. 5 colunas: Indicador (B-E) | Receita R$ (F-H) | Despesa R$ (I-K) | Variação (L-M) | % sobre Bruto (N-O). Layout em grade com alternância de cores branco/cinza.
B36: Coluna Variação | C36: Receita_linha - Despesa_linha (diferenca por linha) | D36: Para cada linha, a diferença mostra se a receita supera a despesa naquele indicador específico. Formatação condicional de cor: positivo exibe normal (azul), negativo exibe entre parênteses em vermelho via formato "#,##0.00;[Red](#,##0.00)".
B37: Coluna % sobre Bruto | C37: Valor_linha / _DadosAux!B1 (proporcao sobre bruto) | D37: Cada valor de receita é dividido pelo Bruto Total de Receita. Mostra qual percentual do faturamento bruto aquele indicador representa. Ex: Pendente = 15,2% do bruto = 15,2% em risco.
B38: Linha de Total | C38: _DadosAux!B1 e _DadosAux!B15 (totais brutos) | D38: A última linha usa fundo navy e traz os totais de Receita Bruta (col F-H) e Despesa Bruta (col I-K) lado a lado, com variação calculada diretamente. Serve como linha de rodapé do bloco analítico.
A39: ▸ SEÇÃO 6 — GRÁFICOS (Linha 33 em diante)
B40: Pizza: Receita por Status | C40: _DadosAux!G1:H4 | D40: 3 fatias: Recebido (verde #1D6A38), Pendente (âmbar #A04000), Atrasado (vermelho #C0392B). Dados vindos de fórmulas _DadosAux que puxam RECEITA!E10, RECEITA!C9 e RECEITA!C10 respectivamente.
B41: Pizza: Despesa por Status | C41: _DadosAux!J1:K4 | D41: 3 fatias: Pago (verde), Em Aberto (âmbar), Atrasado (vermelho). Dados de DESPESA!F10, C9, C10. Mesma paleta da pizza de receita para facilitar comparação visual entre os dois padrões.
...

Sheet _DadosAux
A1: RECEITA_BRUTA | B1: =RECEITA!C7 -> 57740.65 | D1: Categoria Despesa | E1: Valor | G1: Status Receita | H1: Valor | J1: Status Despesa | K1: Valor | M1: Comparativo | N1: Receita | O1: Despesa | Q1: Cat Receita | R1: Valor | S1: Indicador | T1: Percentual
A2: RECEITA_RECEBIDA | B2: =RECEITA!E10 -> 12693.55 | D2: Operacional | E2: =_DadosAux!B19 -> 108688.81 | G2: Recebido | H2: =_DadosAux!B2 -> 12693.55 | J2: Pago | K2: =_DadosAux!B16 -> 123325.19 | M2: Bruto | N2: =_DadosAux!B1 -> 57740.65 | O2: =_DadosAux!B15 -> 167793.31 | Q2: Venda | R2: =_DadosAux!B12 -> 52349.5 | S2: Efic. Cobrança (Rec) | T2: =_DadosAux!B31 -> 0.21983732
A3: RECEITA_PENDENTE | B3: =RECEITA!C9 -> 2896.15 | D3: Financeiro | E3: =_DadosAux!B20 -> 47154.02 | G3: Pendente | H3: =_DadosAux!B3 -> 2896.15 | J3: Em Aberto | K3: =_DadosAux!B17 -> 31823.43 | M3: Realizado | N3: =_DadosAux!B2 -> 12693.55 | O3: =_DadosAux!B16 -> 123325.19 | Q3: Locação | R3: =_DadosAux!B13 -> 5391.15 | S3: Efic. Pagamento (Desp) | T3: =_DadosAux!B32 -> 0.73498276
A4: RECEITA_ATRASADA | B4: =RECEITA!C10 -> 14647.51 | D4: Administrativo | E4: =_DadosAux!B21 -> 9050.59 | G4: Atrasado | H4: =_DadosAux!B4 -> 14647.51 | J4: Atrasado | K4: =_DadosAux!B18 -> 12590.75 | M4: Em Risco | N4: =_DadosAux!B33 -> 17543.66 | O4: =_DadosAux!B34 -> 44414.18 | S4: Comprometimento | T4: =_DadosAux!B30 -> 9.7155792
A5: RECEITA_BOLETO | B5: =RECEITA!E8 -> 28780.088 | D5: Investimento | E5: =_DadosAux!B22 -> 2899.89
A6: RECEITA_CARTAO | B6: =SUMIF(RECEITA!H16:H27,"Cartao",RECEITA!G16:G27) -> 0
A7: RECEITA_DEPOSITO | B7: =RECEITA!E9 -> 1237.5
A8: REC_COUNT | B8: =COUNTA(RECEITA!A16:A27) -> 12
A9: REC_RECEBIDO_CT | B9: =COUNTIF(RECEITA!I16:I27,"Recebido") -> 7
A10: REC_PENDENTE_CT | B10: =COUNTIF(RECEITA!I16:I27,"Pendente") -> 1
A11: REC_ATRASADO_CT | B11: =COUNTIF(RECEITA!I16:I27,"Atrasado") -> 4
A12: REC_VENDA | B12: =SUMIF(RECEITA!D16:D27,"Venda",RECEITA!G16:G27) -> 52349.5
A13: REC_LOCACAO | B13: =SUMIF(RECEITA!D16:D27,"Locação",RECEITA!G16:G27) -> 5391.15
A15: DESP_BRUTA | B15: =DESPESA!C7 -> 167793.31
A16: DESP_PAGA | B16: =DESPESA!F10 -> 123325.19
A17: DESP_EMABERTO | B17: =DESPESA!C9 -> 31823.43
A18: DESP_ATRASADA | B18: =DESPESA!C10 -> 12590.75
A19: DESP_OP | B19: =SUMIF(DESPESA!D15:D27,"Operacional",DESPESA!H15:H27) -> 108688.81
A20: DESP_FIN | B20: =SUMIF(DESPESA!D15:D27,"Financeiro",DESPESA!H15:H27) -> 47154.02
A21: DESP_ADM | B21: =SUMIF(DESPESA!D15:D27,"Administrativo",DESPESA!H15:H27) -> 9050.59
A22: DESP_INV | B22: =SUMIF(DESPESA!D15:D27,"Investimento",DESPESA!H15:H27) -> 2899.89
A23: DESP_COUNT | B23: =COUNTA(DESPESA!A15:A27) -> 13
A24: DESP_QUITADO_CT | B24: =COUNTIF(DESPESA!J15:J27,"Quitado") -> 5
A25: DESP_ATRASADO_CT | B25: =COUNTIF(DESPESA!J15:J27,"Atrasado") -> 4
A26: DESP_EMABERTO_CT | B26: =COUNTIF(DESPESA!J15:J27,"Em Aberto") -> 4
A28: RESULTADO | B28: =_DadosAux!B2-_DadosAux!B16 -> -110631.64
A29: MARGEM | B29: =IFERROR((_DadosAux!B2-_DadosAux!B16)/_DadosAux!B2,0) -> -8.7155792
A30: COMPROMETIMENTO | B30: =IFERROR(_DadosAux!B16/_DadosAux!B2,0) -> 9.7155792
A31: EFIC_REC | B31: =IFERROR(_DadosAux!B2/_DadosAux!B1,0) -> 0.21983732
A32: EFIC_DESP | B32: =IFERROR(_DadosAux!B16/_DadosAux!B15,0) -> 0.73498276
A33: SALDO_RISCO_REC | B33: =_DadosAux!B3+_DadosAux!B4 -> 17543.66
A34: SALDO_RISCO_DESP | B34: =_DadosAux!B17+_DadosAux!B18 -> 44414.18
A35: TICKET_REC | B35: =IFERROR(_DadosAux!B1/_DadosAux!B8,0) -> 4811.7208
A36: TICKET_DESP | B36: =IFERROR(_DadosAux!B15/_DadosAux!B23,0) -> 12907.178
S37: Developed by Mara N,
